Workbook

Sheet วิธีใช้
B1: REVERSE DCF SCREENER — Terminal-Anchored
B2: เครื่องมือคัดหุ้นด้วยความคาดหวังที่ราคาฝังไว้ | จัดทำโดย Earthh Evans · แจกฟรีห้ามจำหน่าย
B5: แนวคิด (ทำไมเครื่องมือนี้ต่างจาก screener ทั่วไป)
B6: Screener ทั่วไปใช้ P/E, PEG, EV/EBITDA ย้อนหลัง = มองอดีต เครื่องมือนี้พลิกคำถามเป็น "ราคาวันนี้กำลังเรียกร้องให้บริษัทโตปีละกี่ %" (Market-Implied CAGR) แล้วเทียบกับ "เพดานโตที่เป็นไปได้จริง" (Plausible CAGR) ส่วนต่าง (Gap) = คำตอบว่าแพงหรือถูก output ไม่ใช่ราคาเป้าหมาย (เปราะ) แต่เป็นเกจวัดความคาดหวัง (ทนทานกว่า)
B8: ตรรกะหลัก (Terminal-Anchored Reverse DCF)
B9: 1) สมมติมูลค่าเกือบทั้งก้อนอยู่ปลายทาง (เหมาะกับหุ้น growth / pre-profit) 2) ก้อนปลายทาง TV(ปีN)=EV×(1+WACC)^N 3) FCFF ปีถัดไป=TV×(WACC−g) จากสูตร Gordon 4) ถอดเป็นรายได้: R*=FCFF÷[margin×(1−tax)×(1−reinvestment)] โดย reinvestment=g÷ROIC 5) Implied CAGR=(R*/รายได้วันนี้)^(1/(N+1))−1
B11: Plausible CAGR คิดแบบ Heuristic อัตโนมัติ = ค่าที่ต่ำที่สุดของ 3 เพดาน
B12: Cap A (Historical): Hist CAGR 3 ปี × Fade factor (โตจริงมัน decay ตามสเกล) | Cap B (TAM): CAGR ที่ทำให้รายได้ปลายทาง = MaxPenetration% × TAM | Cap C (Absolute): เพดานแข็ง (default 45% เพราะการคงโต >50% สิบปีแทบไม่มีในประวัติศาสตร์) → Plausible = MIN(A,B,C) = ข้อจำกัดที่ผูกมัดที่สุดชนะ
B14: คำตัดสิน (Verdict)
B15: Gap = Implied − Plausible ถ้า Gap > Buffer → แพง (Priced for Perfection) | อยู่ในกรอบ ±Buffer → Fair | Gap < −Buffer → ถูก (Low Expectations)
B17: วิธีใช้ทีละสเตป
B18: • Engine = เครื่องคิดเลขหุ้นเดี่ยว โชว์ทุกสเตป (ใช้สอน/ทำคอนเทนต์ได้) — มีเคส SpaceX กรอกตัวอย่างไว้แล้ว • Screener = ตารางเทียบหลายตัว ระบายสีแพง/ถูกอัตโนมัติ • Sensitivity = ตาราง Implied CAGR ตาม WACC × margin ของหุ้นใน Engine • WACC_Damodaran = ตาราง lookup ต้นทุนเงินรายอุตสาหกรรม • AI_Prompts = prompt ดึงงบมากรอก
... B38: • ถ้า verdict → แพง ไม่ได้แปลว่าขาย — แปลว่า "ราคาตอนนี้ต้องการ perfection — พลาดนิดเดียวก็ร่วงหนัก"

Sheet WACC_Damodaran
A1: WACC / Cost of Capital รายอุตสาหกรรม
A2: ⚠ ค่าตัวอย่าง (ILLUSTRATIVE) — แทนที่ด้วยข้อมูลจริงจาก Damodaran 'Cost of Capital by Industry Sector (US)' อัปเดต ม.ค. ทุกปี
A3: Industry / Sector | B3: Cost of Capital | C3: หมายเหตุ
A4: Software (System/Application) | B4: 0.095 | C4: ตัวเลขในคอลัมน์นี้ทั้งหมดเป็น placeholder — โหลดของจริงจาก pages.stern.nyu.edu/~adamodar มาทับ
A5: Semiconductor | B5: 0.11
A6: Computers/Peripherals | B6: 0.09
A7: Internet/E-commerce Retail | B7: 0.095
A8: Telecom Services | B8: 0.07
A9: Aerospace/Defense | B9: 0.085
A10: Auto & Truck | B10: 0.085
A11: Banks (Money Center) | B11: 0.09
A12: Pharma (Drugs) | B12: 0.075
A13: Biotechnology | B13: 0.095
A14: Healthcare Products | B14: 0.075
A15: Retail (General) | B15: 0.075
A16: Food Processing | B16: 0.06
... A28: Total Market (Avg) | B28: 0.083

Sheet Engine
B1: ENGINE — Reverse DCF หุ้นเดี่ยว (Terminal-Anchored) | F1: SENSITIVITY — Implied CAGR ตาม WACC × Terminal Margin
B3: 1) INPUT — ข้อมูลบริษัท (กรอกช่องเหลือง) | F3: แถว = WACC | คอลัมน์ = Terminal EBIT margin | ค่าอื่นดึงจากฝั่งซ้าย (g, ROIC, tax, N, EV, R0)
B4: Ticker / ชื่อหุ้น
B5: Current Revenue — R0 ($B) | D5: รายได้ FY ล่าสุด | F5: WACC \ margin | G5: 0.2 | H5: 0.25 | I5: 0.3 | J5: 0.35 | K5: 0.4
B6: Enterprise Value anchor — EV ($B) | D6: ≈ mktcap + net debt - Cash | F6: 0.08 | G6: =(((($C$6*(1+$F6)^$C$15*($F6-$C$12))/(G$5*(1-$C$14)*(1-$C$12/$C$13)))/$C$5)^(1/($C$15+1))-1) | H6: =(((($C$6*(1+$F6)^$C$15*($F6-$C$12))/(H$5*(1-$C$14)*(1-$C$12/$C$13)))/$C$5)^(1/($C$15+1))-1) | I6: =(((($C$6*(1+$F6)^$C$15*($F6-$C$12))/(I$5*(1-$C$14)*(1-$C$12/$C$13)))/$C$5)^(1/($C$15+1))-1) | J6: =(((($C$6*(1+$F6)^$C$15*($F6-$C$12))/(J$5*(1-$C$14)*(1-$C$12/$C$13)))/$C$5)^(1/($C$15+1))-1) | K6: =(((($C$6*(1+$F6)^$C$15*($F6-$C$12))/(K$5*(1-$C$14)*(1-$C$12/$C$13)))/$C$5)^(1/($C$15+1))-1)
B7: Sector (เลือก dropdown) | D7: ใช้ดึง WACC จากตาราง Damodaran | F7: 0.09 | G7: =(((($C$6*(1+$F7)^$C$15*($F7-$C$12))/(G$5*(1-$C$14)*(1-$C$12/$C$13)))/$C$5)^(1/($C$15+1))-1) | H7: =(((($C$6*(1+$F7)^$C$15*($F7-$C$12))/(H$5*(1-$C$14)*(1-$C$12/$C$13)))/$C$5)^(1/($C$15+1))-1) | I7: =(((($C$6*(1+$F7)^$C$15*($F7-$C$12))/(I$5*(1-$C$14)*(1-$C$12/$C$13)))/$C$5)^(1/($C$15+1))-1) | J7: =(((($C$6*(1+$F7)^$C$15*($F7-$C$12))/(J$5*(1-$C$14)*(1-$C$12/$C$13)))/$C$5)^(1/($C$15+1))-1) | K7: =(((($C$6*(1+$F7)^$C$15*($F7-$C$12))/(K$5*(1-$C$14)*(1-$C$12/$C$13)))/$C$5)^(1/($C$15+1))-1)
B8: WACC (auto จาก sector) | C8: =IFERROR(VLOOKUP(C7,WACC_Damodaran!$A$4:$B$28,2,FALSE()),"") | D8: ลิงก์จากชีต WACC_Damodaran | F8: 0.1 | G8: =(((($C$6*(1+$F8)^$C$15*($F8-$C$12))/(G$5*(1-$C$14)*(1-$C$12/$C$13)))/$C$5)^(1/($C$15+1))-1) | H8: =(((($C$6*(1+$F8)^$C$15*($F8-$C$12))/(H$5*(1-$C$14)*(1-$C$12/$C$13)))/$C$5)^(1/($C$15+1))-1) | I8: =(((($C$6*(1+$F8)^$C$15*($F8-$C$12))/(I$5*(1-$C$14)*(1-$C$12/$C$13)))/$C$5)^(1/($C$15+1))-1) | J8: =(((($C$6*(1+$F8)^$C$15*($F8-$C$12))/(J$5*(1-$C$14)*(1-$C$12/$C$13)))/$C$5)^(1/($C$15+1))-1) | K8: =(((($C$6*(1+$F8)^$C$15*($F8-$C$12))/(K$5*(1-$C$14)*(1-$C$12/$C$13)))/$C$5)^(1/($C$15+1))-1)
B9: WACC override (เว้นว่าง=ใช้ auto) | D9: เคสนี้ override เป็น 10% | F9: 0.11 | G9: =(((($C$6*(1+$F9)^$C$15*($F9-$C$12))/(G$5*(1-$C$14)*(1-$C$12/$C$13)))/$C$5)^(1/($C$15+1))-1) | H9: =(((($C$6*(1+$F9)^$C$15*($F9-$C$12))/(H$5*(1-$C$14)*(1-$C$12/$C$13)))/$C$5)^(1/($C$15+1))-1) | I9: =(((($C$6*(1+$F9)^$C$15*($F9-$C$12))/(I$5*(1-$C$14)*(1-$C$12/$C$13)))/$C$5)^(1/($C$15+1))-1) | J9: =(((($C$6*(1+$F9)^$C$15*($F9-$C$12))/(J$5*(1-$C$14)*(1-$C$12/$C$13)))/$C$5)^(1/($C$15+1))-1) | K9: =(((($C$6*(1+$F9)^$C$15*($F9-$C$12))/(K$5*(1-$C$14)*(1-$C$12/$C$13)))/$C$5)^(1/($C$15+1))-1)
B10: WACC ที่ใช้ | C10: =IF(C9="",C8,C9) | F10: 0.12 | G10: =(((($C$6*(1+$F10)^$C$15*($F10-$C$12))/(G$5*(1-$C$14)*(1-$C$12/$C$13)))/$C$5)^(1/($C$15+1))-1) | H10: =(((($C$6*(1+$F10)^$C$15*($F10-$C$12))/(H$5*(1-$C$14)*(1-$C$12/$C$13)))/$C$5)^(1/($C$15+1))-1) | I10: =(((($C$6*(1+$F10)^$C$15*($F10-$C$12))/(I$5*(1-$C$14)*(1-$C$12/$C$13)))/$C$5)^(1/($C$15+1))-1) | J10: =(((($C$6*(1+$F10)^$C$15*($F10-$C$12))/(J$5*(1-$C$14)*(1-$C$12/$C$13)))/$C$5)^(1/($C$15+1))-1) | K10: =(((($C$6*(1+$F10)^$C$15*($F10-$C$12))/(K$5*(1-$C$14)*(1-$C$12/$C$13)))/$C$5)^(1/($C$15+1))-1)
B11: Terminal EBIT margin | D11: margin ตอนโตเต็มวัย
B12: Terminal growth g | D12: โตนิ่งระยะยาว (≈ GDP+) | F12: WACC × PRICE — ราคาโซนไหนน่าสนใจ
B13: Terminal ROIC | D13: ผลตอบแทนต่อทุนตอน mature
B14: Tax rate | F14: ค่า = Implied CAGR ที่ราคานั้นบังคับ. เขียว ≤ Plausible (ถูก), เหลือง = Caution, แดง ≥ Plausible+10pp (แพง)
B15: Horizon N (ปี explicit) | D15: รายได้ปลายทาง = ปีที่ N+1
F16: WACC \ Price | G16: =$C$43*0.6 | H16: =$C$43*0.8 | I16: =$C$43 | J16: =$C$43*1.2 | K16: =$C$43*1.4
B17: 2) HEURISTIC INPUT — เพดานโตที่เป็นจริง | F17: 0.08 | G17: =(((((G$16*$C$44/1000+$C$45)*(1+$F17)^$C$15)*($F17-$C$12))/($C$11*(1-$C$14)*(1-$C$12/$C$13)))/$C$5)^(1/($C$15+1))-1 | H17: =(((((H$16*$C$44/1000+$C$45)*(1+$F17)^$C$15)*($F17-$C$12))/($C$11*(1-$C$14)*(1-$C$12/$C$13)))/$C$5)^(1/($C$15+1))-1 | I17: =(((((I$16*$C$44/1000+$C$45)*(1+$F17)^$C$15)*($F17-$C$12))/($C$11*(1-$C$14)*(1-$C$12/$C$13)))/$C$5)^(1/($C$15+1))-1 | J17: =(((((J$16*$C$44/1000+$C$45)*(1+$F17)^$C$15)*($F17-$C$12))/($C$11*(1-$C$14)*(1-$C$12/$C$13)))/$C$5)^(1/($C$15+1))-1 | K17: =(((((K$16*$C$44/1000+$C$45)*(1+$F17)^$C$15)*($F17-$C$12))/($C$11*(1-$C$14)*(1-$C$12/$C$13)))/$C$5)^(1/($C$15+1))-1
B18: Historical Revenue CAGR (3yr) | D18: track record การโต | F18: 0.09 | G18: =(((((G$16*$C$44/1000+$C$45)*(1+$F18)^$C$15)*($F18-$C$12))/($C$11*(1-$C$14)*(1-$C$12/$C$13)))/$C$5)^(1/($C$15+1))-1 | H18: =(((((H$16*$C$44/1000+$C$45)*(1+$F18)^$C$15)*($F18-$C$12))/($C$11*(1-$C$14)*(1-$C$12/$C$13)))/$C$5)^(1/($C$15+1))-1 | I18: =(((((I$16*$C$44/1000+$C$45)*(1+$F18)^$C$15)*($F18-$C$12))/($C$11*(1-$C$14)*(1-$C$12/$C$13)))/$C$5)^(1/($C$15+1))-1 | J18: =(((((J$16*$C$44/1000+$C$45)*(1+$F18)^$C$15)*($F18-$C$12))/($C$11*(1-$C$14)*(1-$C$12/$C$13)))/$C$5)^(1/($C$15+1))-1 | K18: =(((((K$16*$C$44/1000+$C$45)*(1+$F18)^$C$15)*($F18-$C$12))/($C$11*(1-$C$14)*(1-$C$12/$C$13)))/$C$5)^(1/($C$15+1))-1
B19: Fade factor (growth decay) | D19: หักลบเพราะโตจริงมันชะลอตามสเกล | F19: 0.1 | G19: =(((((G$16*$C$44/1000+$C$45)*(1+$F19)^$C$15)*($F19-$C$12))/($C$11*(1-$C$14)*(1-$C$12/$C$13)))/$C$5)^(1/($C$15+1))-1 | H19: =(((((H$16*$C$44/1000+$C$45)*(1+$F19)^$C$15)*($F19-$C$12))/($C$11*(1-$C$14)*(1-$C$12/$C$13)))/$C$5)^(1/($C$15+1))-1 | I19: =(((((I$16*$C$44/1000+$C$45)*(1+$F19)^$C$15)*($F19-$C$12))/($C$11*(1-$C$14)*(1-$C$12/$C$13)))/$C$5)^(1/($C$15+1))-1 | J19: =(((((J$16*$C$44/1000+$C$45)*(1+$F19)^$C$15)*($F19-$C$12))/($C$11*(1-$C$14)*(1-$C$12/$C$13)))/$C$5)^(1/($C$15+1))-1 | K19: =(((((K$16*$C$44/1000+$C$45)*(1+$F19)^$C$15)*($F19-$C$12))/($C$11*(1-$C$14)*(1-$C$12/$C$13)))/$C$5)^(1/($C$15+1))-1
B20: TAM ($B) | F20: 0.11 | G20: =(((((G$16*$C$44/1000+$C$45)*(1+$F20)^$C$15)*($F20-$C$12))/($C$11*(1-$C$14)*(1-$C$12/$C$13)))/$C$5)^(1/($C$15+1))-1 | H20: =(((((H$16*$C$44/1000+$C$45)*(1+$F20)^$C$15)*($F20-$C$12))/($C$11*(1-$C$14)*(1-$C$12/$C$13)))/$C$5)^(1/($C$15+1))-1 | I20: =(((((I$16*$C$44/1000+$C$45)*(1+$F20)^$C$15)*($F20-$C$12))/($C$11*(1-$C$14)*(1-$C$12/$C$13)))/$C$5)^(1/($C$15+1))-1 | J20: =(((((J$16*$C$44/1000+$C$45)*(1+$F20)^$C$15)*($F20-$C$12))/($C$11*(1-$C$14)*(1-$C$12/$C$13)))/$C$5)^(1/($C$15+1))-1 | K20: =(((((K$16*$C$44/1000+$C$45)*(1+$F20)^$C$15)*($F20-$C$12))/($C$11*(1-$C$14)*(1-$C$12/$C$13)))/$C$5)^(1/($C$15+1))-1
B21: Max penetration % | D21: ไม่มีใครกิน 100% ของ TAM | F21: 0.12 | G21: =(((((G$16*$C$44/1000+$C$45)*(1+$F21)^$C$15)*($F21-$C$12))/($C$11*(1-$C$14)*(1-$C$12/$C$13)))/$C$5)^(1/($C$15+1))-1 | H21: =(((((H$16*$C$44/1000+$C$45)*(1+$F21)^$C$15)*($F21-$C$12))/($C$11*(1-$C$14)*(1-$C$12/$C$13)))/$C$5)^(1/($C$15+1))-1 | I21: =(((((I$16*$C$44/1000+$C$45)*(1+$F21)^$C$15)*($F21-$C$12))/($C$11*(1-$C$14)*(1-$C$12/$C$13)))/$C$5)^(1/($C$15+1))-1 | J21: =(((((J$16*$C$44/1000+$C$45)*(1+$F21)^$C$15)*($F21-$C$12))/($C$11*(1-$C$14)*(1-$C$12/$C$13)))/$C$5)^(1/($C$15+1))-1 | K21: =(((((K$16*$C$44/1000+$C$45)*(1+$F21)^$C$15)*($F21-$C$12))/($C$11*(1-$C$14)*(1-$C$12/$C$13)))/$C$5)^(1/($C$15+1))-1
B22: Absolute ceiling CAGR | D22: เพดานแข็ง
B23: Forward CAGR (FY+1 guidance) | C23: =IF(C50>0,C50/C5-1,"") | D23: ดึงจาก C50/C5−1 (ถ้า C50 มีข้อมูล) | F23: 📌 VERDICT — หุ้นถูกหรือแพงยังไง?
B24: 3) REVERSE DCF ENGINE — คำนวณอัตโนมัติ | F24: ราคาปัจจุบัน: | H24: =TEXT($C$43,"$0.00")&" | mkt cap "&TEXT($C$46,"$0.0")&"B | EV "&TEXT($C$6,"$0.0")&"B"
B25: Reinvestment = g ÷ ROIC | C25: =C12/C13 | D25: กำไรที่ต้องโปะกลับเพื่อโต g | F25: Implied CAGR (ตลาดต้องการ): | H25: =TEXT($C$30,"0.0%")&" ต่อปี ตลอด "&$C$15&" ปี"
B26: Terminal Value ปีN = EV×(1+WACC)^N ($B) | C26: =C6*(1+C10)^C15 | F26: Plausible CAGR: | H26: =TEXT($C$36,"0.0%")&" (Hist "&TEXT($C$18,"0.0%")&" × Fade "&TEXT($C$19,"0.00")&")"
B27: FCFF ปีN+1 = TV×(WACC−g) ($B) | C27: =C26*(C10-C12) | D27: Gordon: TV=FCFF/(WACC−g) | F27: ="⚡ Gap = "&IF($C$39>=0,"+","")&TEXT($C$39*100,"0.0")&"pp"
B28: Conversion = margin×(1−tax)×(1−reinv) | C28: =C11*(1-C14)*(1-C25) | D28: รายได้ $1 → เงินสดอิสระกี่เซนต์ | F28: ="คำตัดสิน: "&$C$41
B29: Implied Terminal Revenue R* ($B) | C29: =C27/C28 | F29: 📊 ทำไมถึงแพง?
B30: ► Market-Implied Revenue CAGR | C30: =(C29/C5)^(1/(C15+1))-1 | D30: ราคาบังคับให้โตปีละเท่านี้ | F30: ="• EV/Sales = "&TEXT($C$6/$C$5,"0.0")&"x | Hist CAGR 3yr = "&TEXT($C$18,"0%")&" | Forward CAGR (FY+1 guide) = "&IF(ISNUMBER($C$23),TEXT($C$23,"0%"),"N/A")&" → Cap A ใช้ตัวที่สูงกว่า"
B32: 4) PLAUSIBLE CAGR (Heuristic)
B33: Cap A: MAX(Hist, Forward) × Fade | C33: =MAX(C18,IF(ISNUMBER(C23),C23,0))*C19 | F33: 💰 ช่วงราคาน่าสะสม (อิง WACC base และ Plausible CAGR)
B34: Cap B: TAM-constrained | C34: =IF(C20=0,999,(C21*C20/C5)^(1/(C15+1))-1) | F34: 🟢🟢 สะสมสบายใจ (ราคา ≤) | I34: =(($C$5*(1+MAX($C$36-0.05,0))^($C$15+1)*($C$11*(1-$C$14)*(1-$C$12/$C$13))/($C$10-$C$12)/(1+$C$10)^$C$15)-$C$45)*1000/$C$44
B35: Cap C: Absolute ceiling | C35: =C22 | F35: 🟢 Fair Value (Implied = Plausible) | I35: =(($C$5*(1+$C$36)^($C$15+1)*($C$11*(1-$C$14)*(1-$C$12/$C$13))/($C$10-$C$12)/(1+$C$10)^$C$15)-$C$45)*1000/$C$44
B36: ► Plausible CAGR = MIN(A,B,C) | C36: =MIN(C33,C34,C35) | D36: เพดานที่เป็นจริงที่สุด | F36: ⚠️ รอดู (Gap +5 ถึง +10pp) | I36: =TEXT((($C$5*(1+$C$36+0.05)^($C$15+1)*($C$11*(1-$C$14)*(1-$C$12/$C$13))/($C$10-$C$12)/(1+$C$10)^$C$15)-$C$45)*1000/$C$44,"$0.00")&" – "&TEXT((($C$5*(1+$C$36+0.1)^($C$15+1)*($C$11*(1-$C$14)*(1-$C$12/$C$13))/($C$10-$C$12)/(1+$C$10)^$C$15)-$C$45)*1000/$C$44,"$0.00")
F37: 🔴 แพง — อย่าซื้อ (ราคา >) | I37: =TEXT((($C$5*(1+$C$36+0.1)^($C$15+1)*($C$11*(1-$C$14)*(1-$C$12/$C$13))/($C$10-$C$12)/(1+$C$10)^$C$15)-$C$45)*1000/$C$44,"$0.00")&" (ปัจจุบัน "&TEXT($C$43,"$0.00")&")"
B38: 5) VERDICT
B39: Expectation Gap = Implied − Plausible | C39: =C30-C36
B40: Buffer (±)
B41: ► คำตัดสิน | C41: =IF(C39>C40,"แพง — Priced for Perfection",IF(C39<-C40,"ถูก — Low Expectations","Fair — สมเหตุสมผล"))
B42: 6) PRICE INPUT (สำหรับตาราง Upside)
...

Sheet Screener
A1: SCREENER — ตารางเทียบหุ้น แพง/ถูก ด้วย Implied CAGR
R2: GLOBAL ASSUMPTIONS
R3: Tax rate | S3: 0.21
R4: Fade factor | S4: 0.7
R5: Max penetration | S5: 0.25
R6: Absolute ceiling | S6: 0.45
R7: Buffer (±) | S7: 0.05
A9: Ticker | B9: Sector | C9: WACC | D9: Revenue R0 ($B) | E9: EV ($B) | F9: Term margin | G9: g | H9: ROIC | I9: N (yr) | J9: Hist CAGR 3y | K9: TAM ($B) | L9: Reinv | M9: Implied CAGR | N9: Plausible CAGR | O9: Gap (pp) | P9: Verdict | Q9: WACC override
C10: =IF($B10="","",IF($Q10<>"",$Q10,IFERROR(VLOOKUP($B10,WACC_Damodaran!$A$4:$B$28,2,FALSE()),""))) | L10: =IF($H10=0,"",$G10/$H10) | M10: =IF(OR($D10=0,$C10=""),"",((($E10*(1+$C10)^$I10*($C10-$G10))/($F10*(1-$S$3)*(1-$G10/$H10)))/$D10)^(1/($I10+1))-1) | N10: =IF($D10=0,"",MIN($J10*$S$4,IF($K10=0,999,($S$5*$K10/$D10)^(1/($I10+1))-1),$S$6)) | O10: =IF($M10="","",$M10-$N10) | P10: =IF($M10="","",IF($O10>$S$7,"แพง — Priced for Perfection",IF($O10<-$S$7,"ถูก — Low Expectations","Fair — สมเหตุสมผล")))
C11: =IF($B11="","",IF($Q11<>"",$Q11,IFERROR(VLOOKUP($B11,WACC_Damodaran!$A$4:$B$28,2,FALSE()),""))) | L11: =IF($H11=0,"",$G11/$H11) | M11: =IF(OR($D11=0,$C11=""),"",((($E11*(1+$C11)^$I11*($C11-$G11))/($F11*(1-$S$3)*(1-$G11/$H11)))/$D11)^(1/($I11+1))-1) | N11: =IF($D11=0,"",MIN($J11*$S$4,IF($K11=0,999,($S$5*$K11/$D11)^(1/($I11+1))-1),$S$6)) | O11: =IF($M11="","",$M11-$N11) | P11: =IF($M11="","",IF($O11>$S$7,"แพง — Priced for Perfection",IF($O11<-$S$7,"ถูก — Low Expectations","Fair — สมเหตุสมผล")))
C12: =IF($B12="","",IF($Q12<>"",$Q12,IFERROR(VLOOKUP($B12,WACC_Damodaran!$A$4:$B$28,2,FALSE()),""))) | L12: =IF($H12=0,"",$G12/$H12) | M12: =IF(OR($D12=0,$C12=""),"",((($E12*(1+$C12)^$I12*($C12-$G12))/($F12*(1-$S$3)*(1-$G12/$H12)))/$D12)^(1/($I12+1))-1) | N12: =IF($D12=0,"",MIN($J12*$S$4,IF($K12=0,999,($S$5*$K12/$D12)^(1/($I12+1))-1),$S$6)) | O12: =IF($M12="","",$M12-$N12) | P12: =IF($M12="","",IF($O12>$S$7,"แพง — Priced for Perfection",IF($O12<-$S$7,"ถูก — Low Expectations","Fair — สมเหตุสมผล")))
C13: =IF($B13="","",IF($Q13<>"",$Q13,IFERROR(VLOOKUP($B13,WACC_Damodaran!$A$4:$B$28,2,FALSE()),""))) | L13: =IF($H13=0,"",$G13/$H13) | M13: =IF(OR($D13=0,$C13=""),"",((($E13*(1+$C13)^$I13*($C13-$G13))/($F13*(1-$S$3)*(1-$G13/$H13)))/$D13)^(1/($I13+1))-1) | N13: =IF($D13=0,"",MIN($J13*$S$4,IF($K13=0,999,($S$5*$K13/$D13)^(1/($I13+1))-1),$S$6)) | O13: =IF($M13="","",$M13-$N13) | P13: =IF($M13="","",IF($O13>$S$7,"แพง — Priced for Perfection",IF($O13<-$S$7,"ถูก — Low Expectations","Fair — สมเหตุสมผล")))
C14: =IF($B14="","",IF($Q14<>"",$Q14,IFERROR(VLOOKUP($B14,WACC_Damodaran!$A$4:$B$28,2,FALSE()),""))) | L14: =IF($H14=0,"",$G14/$H14) | M14: =IF(OR($D14=0,$C14=""),"",((($E14*(1+$C14)^$I14*($C14-$G14))/($F14*(1-$S$3)*(1-$G14/$H14)))/$D14)^(1/($I14+1))-1) | N14: =IF($D14=0,"",MIN($J14*$S$4,IF($K14=0,999,($S$5*$K14/$D14)^(1/($I14+1))-1),$S$6)) | O14: =IF($M14="","",$M14-$N14) | P14: =IF($M14="","",IF($O14>$S$7,"แพง — Priced for Perfection",IF($O14<-$S$7,"ถูก — Low Expectations","Fair — สมเหตุสมผล")))
C15: =IF($B15="","",IF($Q15<>"",$Q15,IFERROR(VLOOKUP($B15,WACC_Damodaran!$A$4:$B$28,2,FALSE()),""))) | L15: =IF($H15=0,"",$G15/$H15) | M15: =IF(OR($D15=0,$C15=""),"",((($E15*(1+$C15)^$I15*($C15-$G15))/($F15*(1-$S$3)*(1-$G15/$H15)))/$D15)^(1/($I15+1))-1) | N15: =IF($D15=0,"",MIN($J15*$S$4,IF($K15=0,999,($S$5*$K15/$D15)^(1/($I15+1))-1),$S$6)) | O15: =IF($M15="","",$M15-$N15) | P15: =IF($M15="","",IF($O15>$S$7,"แพง — Priced for Perfection",IF($O15<-$S$7,"ถูก — Low Expectations","Fair — สมเหตุสมผล")))
C16: =IF($B16="","",IF($Q16<>"",$Q16,IFERROR(VLOOKUP($B16,WACC_Damodaran!$A$4:$B$28,2,FALSE()),""))) | L16: =IF($H16=0,"",$G16/$H16) | M16: =IF(OR($D16=0,$C16=""),"",((($E16*(1+$C16)^$I16*($C16-$G16))/($F16*(1-$S$3)*(1-$G16/$H16)))/$D16)^(1/($I16+1))-1) | N16: =IF($D16=0,"",MIN($J16*$S$4,IF($K16=0,999,($S$5*$K16/$D16)^(1/($I16+1))-1),$S$6)) | O16: =IF($M16="","",$M16-$N16) | P16: =IF($M16="","",IF($O16>$S$7,"แพง — Priced for Perfection",IF($O16<-$S$7,"ถูก — Low Expectations","Fair — สมเหตุสมผล")))
C17: =IF($B17="","",IF($Q17<>"",$Q17,IFERROR(VLOOKUP($B17,WACC_Damodaran!$A$4:$B$28,2,FALSE()),""))) | L17: =IF($H17=0,"",$G17/$H17) | M17: =IF(OR($D17=0,$C17=""),"",((($E17*(1+$C17)^$I17*($C17-$G17))/($F17*(1-$S$3)*(1-$G17/$H17)))/$D17)^(1/($I17+1))-1) | N17: =IF($D17=0,"",MIN($J17*$S$4,IF($K17=0,999,($S$5*$K17/$D17)^(1/($I17+1))-1),$S$6)) | O17: =IF($M17="","",$M17-$N17) | P17: =IF($M17="","",IF($O17>$S$7,"แพง — Priced for Perfection",IF($O17<-$S$7,"ถูก — Low Expectations","Fair — สมเหตุสมผล")))
C18: =IF($B18="","",IF($Q18<>"",$Q18,IFERROR(VLOOKUP($B18,WACC_Damodaran!$A$4:$B$28,2,FALSE()),""))) | L18: =IF($H18=0,"",$G18/$H18) | M18: =IF(OR($D18=0,$C18=""),"",((($E18*(1+$C18)^$I18*($C18-$G18))/($F18*(1-$S$3)*(1-$G18/$H18)))/$D18)^(1/($I18+1))-1) | N18: =IF($D18=0,"",MIN($J18*$S$4,IF($K18=0,999,($S$5*$K18/$D18)^(1/($I18+1))-1),$S$6)) | O18: =IF($M18="","",$M18-$N18) | P18: =IF($M18="","",IF($O18>$S$7,"แพง — Priced for Perfection",IF($O18<-$S$7,"ถูก — Low Expectations","Fair — สมเหตุสมผล")))
C19: =IF($B19="","",IF($Q19<>"",$Q19,IFERROR(VLOOKUP($B19,WACC_Damodaran!$A$4:$B$28,2,FALSE()),""))) | L19: =IF($H19=0,"",$G19/$H19) | M19: =IF(OR($D19=0,$C19=""),"",((($E19*(1+$C19)^$I19*($C19-$G19))/($F19*(1-$S$3)*(1-$G19/$H19)))/$D19)^(1/($I19+1))-1) | N19: =IF($D19=0,"",MIN($J19*$S$4,IF($K19=0,999,($S$5*$K19/$D19)^(1/($I19+1))-1),$S$6)) | O19: =IF($M19="","",$M19-$N19) | P19: =IF($M19="","",IF($O19>$S$7,"แพง — Priced for Perfection",IF($O19<-$S$7,"ถูก — Low Expectations","Fair — สมเหตุสมผล")))
A21: หมายเหตุ: Sector ต้องสะกดให้ตรงกับชีต WACC_Damodaran เป๊ะ (พิมพ์ตามหรือก๊อปมา) WACC ถึงจะดึงค่ามา

Sheet AI_Prompts
B1: AI PROMPTS — ดึงงบมากรอกเครื่องมือ
B3: PROMPT A — ดึง input ฟันดาเมนทัล (เปลี่ยน [TICKER] แล้ววางให้ Claude พร้อมไฟล์งบ)
B4: คุณคือ buy-side equity analyst — ดึงข้อมูลเพื่อป้อนโมเดล Reverse DCF หุ้น: [TICKER] === ⚠️ ข้อบังคับสำคัญ (อ่านก่อนลงมือทำงาน) === 1. ตรวจเช็คข้อมูลให้ละเอียด — ลำดับแหล่ง: 10-K/10-Q/20-F ล่าสุด Stock Analysis, Seeking Alpha> earnings presentation/transcript > company guidance > consensus > market data ถ้าขัดกัน → ยึดแหล่ง quality สูงสุด ระบุ time basis ทุกตัว (FY/LTM/NTM) ห้ามเดา — ถ้าไม่มั่นใจเขียน "ต้อง verify" 2. บันทึกลง Engine ทุกครั้ง — ข้อมูลที่ดึงมา ต้องลง cell ใน Engine (C4-C50) พร้อม source note บน cell ทุกตัว 3. บันทึกลง Screener ทุกครั้ง — append แถวใหม่ใน Screener ต่อท้ายแถวเดิม ห้ามลบของเก่า — หาก user ไม่ต้องการ จะสั่งลบเอง 4. Sector ต้องสะกดตรงชีต WACC_Damodaran เป๊ะ (พิมพ์ตามหรือก๊อปมา) ไม่งั้น WACC จะดึงไม่ติด === ข้อมูลที่ต้องส่ง (ตาราง + หน่วย + source) === 1) Current Revenue R0 ($B) — FY ล่าสุด (ระบุไตรมาส/ปีบัญชี) 2) Enterprise Value ($B) = market cap + net debt (ถ้า private ใช้ valuation รอบล่าสุด) 3) Sector — แมปชื่อใน Damodaran (Semiconductor, Aerospace/Defense, Software (System/Application), ฯลฯ) 4) Terminal EBIT margin (%) — ประเมินจาก margin ปัจจุบัน + เพดานอุตสาหกรรม (อย่าสูงเกินจริง) 5) Terminal ROIC (%) — จาก ROIC ปัจจุบัน/peer (ห้ามอย่า hardcode 20% ถ้าจริงต่ำ) 6) Tax rate (%) — effective tax จริง (ระวังบริษัท Cayman/Ireland → ต่ำกว่า 21%) 7) Historical Revenue CAGR 3 ปี (%) — ระบุ base period ชัด (peak→now / trough→now / cycle blend) 8) TAM ($B) + Forward CAGR FY+1 (%) — จากบริษัท guidance หรือ consensus 9) Current price + Shares outstanding + Net debt — สำหรับตาราง WACC × Price 10) Analyst consensus avg target + range + FY+1 revenue consensus === ปิดท้ายด้วย flag === • มูลค่าบริษัทส่วนใหญ่อยู่ปลายทางหรือยัง (เหมาะ Terminal-Anchored ไหม) Y/N + เหตุผล • สิ่งที่ต้อง verify เพิ่ม (ตัวเลขที่ไม่มั่นใจ 100%)
B6: Workflow: 1) รัน Prompt A → AI ดึงข้อมูล verify จาก official sources 2) AI บันทึกลง Engine ให้เอง + append ลง Screener ทุกครั้ง (ไม่ต้องสั่ง) 3) เครื่องมือคำนวณ Implied vs Plausible CAGR + verdict ให้เอง — Plausible CAGR heuristic อยู่ในไฟล์อยู่แล้ว ไม่ต้องถาม AI ซ้ำ 4) User ลบแถว Screener ออกเองตามต้องการ
B8: จัดทำโดย Earthh Evans · แจกฟรีห้ามจำหน่าย
